Workbook

Sheet Analysis Summary
B2: JOBTRACK DATASET — REQUIREMENTS-ALIGNED SYNTHETIC DATA
B3: Built to match every entity/field in BRD Section 10 and SRS Section 8
B4: Reference 'today' for overdue/upcoming calculations: 13 Sep 2026
B6: Entity | C6: Row count | D6: Notes
B7: Users | C7: =COUNTA(Users!A2:A6) -> 5 | D7: Registered users
B8: Applications | C8: =COUNTA(Applications!A2:A101) -> 100 | D8: Job application records
B9: StatusHistory | C9: =COUNTA(StatusHistory!A2:A130) -> 129 | D9: Status-change audit trail (FR-STA-03)
B10: Document | C10: =COUNTA(Document!A2:A167) -> 166 | D10: Resume / cover letter versions (FR-DOC-01/02)
B11: Interview | C11: =COUNTA(Interview!A2:A64) -> 63 | D11: Interview rounds (FR-INT-01/02)
B12: FollowUp | C12: =COUNTA(FollowUp!A2:A43) -> 42 | D12: Follow-up reminders (FR-INT-03/04)
B14: Applications by CurrentStatus (FR-DASH-04)
B15: Status | C15: Count
B16: Applied | C16: =COUNTIF(Applications!$G$2:$G$101,B16) -> 22
B17: Interview | C17: =COUNTIF(Applications!$G$2:$G$101,B17) -> 18
B18: Offer | C18: =COUNTIF(Applications!$G$2:$G$101,B18) -> 8
B19: Rejected | C19: =COUNTIF(Applications!$G$2:$G$101,B19) -> 24
B20: Withdrawn | C20: =COUNTIF(Applications!$G$2:$G$101,B20) -> 12
B21: Archived | C21: =COUNTIF(Applications!$G$2:$G$101,B21) -> 16
B23: Applications by Platform (FR-DASH-05)
B24: Platform | C24: Count
B25: SEEK | C25: =COUNTIF(Applications!$E$2:$E$101,B25) -> 18
B26: LinkedIn | C26: =COUNTIF(Applications!$E$2:$E$101,B26) -> 16
B27: Indeed | C27: =COUNTIF(Applications!$E$2:$E$101,B27) -> 17
B28: Company Website | C28: =COUNTIF(Applications!$E$2:$E$101,B28) -> 23
B29: Referral | C29: =COUNTIF(Applications!$E$2:$E$101,B29) -> 26
B31: Dashboard-style live metrics (FR-DASH-01/02/03)
B32: Metric | C32: Value
B33: Active (non-archived) applications | C33: =COUNTIFS(Applications!$G$2:$G$101,"<>Archived") -> 84
B34: Upcoming interviews (next 7 days) | C34: =COUNTIFS(Interview!$C$2:$C$64,">="&$C36,Interview!$C$2:$C$64,"<="&($C36+7)) -> 10
B35: Overdue follow-ups (not completed, date passed) | C35: =COUNTIFS(FollowUp!$C$2:$C$43,"<"&$C36,FollowUp!$E$2:$E$43,FALSE()) -> 13
B36: Reference 'today' date used above: | C36: 46278

Sheet Users
A1: UserId | B1: Email | C1: PasswordHash | D1: CreatedDate | E1: Name | G1: Note: 'Name' is supplementary (not part of the BRD/SRS User entity) — kept only as a readable label.
A2: U001 | B2: prince.sah@example.com | C2: $2b$12$2mYTi7v3qCEU.zUD6xf.s71zc7BwnGuKlaOcGLpyLWODDT.pLW6U. | D2: 46174 | E2: Prince Kumar Sah
A3: U002 | B3: pooja.tiwari@example.com | C3: $2b$12$hzlWu0VZzgd/ytcm0qmG3jYlNSvZetmBa3Rzr4BehV3xoTBflDU8c | D3: 46176 | E3: Pooja Tiwari
A4: U003 | B4: trinh.tran@example.com | C4: $2b$12$1CsqJ9ql3gECf1dquN7Jk4Ljm2liYOt1i/kwfmk2i9g/IdhAxolkE | D4: 46178 | E4: Trinh Hieu Tran
A5: U004 | B5: demo.user4@example.com | C5: $2b$12$/UC756ZdQi85lLReDhODarYReEXhIZqGW2zzG6zrrGxdWzR5Ut3Xm | D5: 46183 | E5: Demo User 4
A6: U005 | B6: demo.user5@example.com | C6: $2b$12$1nyARhtViEasdqtlP3Mdp2p9gLdFcXK4hx.2.Y4vE7qw8wuc7tTdP | D6: 46188 | E6: Demo User 5

Sheet Applications
A1: ApplicationId | B1: UserId | C1: CompanyName | D1: RoleTitle | E1: Platform | F1: ApplicationDate | G1: CurrentStatus | H1: PortfolioLink | I1: GitHubLink
A2: A001 | B2: U001 | C2: Telstra | D2: Business Analyst | E2: Referral | F2: 46265 | G2: Offer
A3: A002 | B3: U002 | C3: ANZ Bank | D3: Graduate Software Developer | E3: Indeed | F3: 46202 | G3: Offer | H3: https://portfolio.dev/u002-a002
A4: A003 | B4: U003 | C4: Atlassian | D4: QA Engineer | E4: Referral | F4: 46175 | G4: Archived | H4: https://portfolio.dev/u003-a003 | I4: https://github.com/u00368
A5: A004 | B5: U004 | C5: DataWorks Australia | D5: Automation Tester | E5: Indeed | F5: 46271 | G5: Applied | H5: https://portfolio.dev/u004-a004
A6: A005 | B6: U005 | C6: Canva | D6: Software Engineer | E6: SEEK | F6: 46204 | G6: Rejected
A7: A006 | B7: U001 | C7: Optus | D7: Network Support Analyst | E7: LinkedIn | F7: 46243 | G7: Rejected | H7: https://portfolio.dev/u001-a006
A8: A007 | B8: U002 | C8: Service NSW | D8: Digital Support Officer | E8: Referral | F8: 46203 | G8: Applied | I8: https://github.com/u00290
A9: A008 | B9: U003 | C9: Qantas | D9: Data Engineer | E9: SEEK | F9: 46239 | G9: Rejected | H9: https://portfolio.dev/u003-a008 | I9: https://github.com/u00383
A10: A009 | B10: U004 | C10: Optus | D10: Network Support Analyst | E10: LinkedIn | F10: 46186 | G10: Applied | H10: https://portfolio.dev/u004-a009 | I10: https://github.com/u00464
A11: A010 | B11: U005 | C11: Accenture Australia | D11: Product Analyst | E11: Company Website | F11: 46267 | G11: Withdrawn | H11: https://portfolio.dev/u005-a010 | I11: https://github.com/u00567
A12: A011 | B12: U001 | C12: Canva | D12: Software Engineer | E12: SEEK | F12: 46230 | G12: Withdrawn | H12: https://portfolio.dev/u001-a011
A13: A012 | B13: U002 | C13: Telstra | D13: Business Analyst | E13: Company Website | F13: 46181 | G13: Applied | H13: https://portfolio.dev/u002-a012 | I13: https://github.com/u00259
A14: A013 | B14: U003 | C14: NSW Government | D14: IT Support Officer | E14: Company Website | F14: 46263 | G14: Rejected | H14: https://portfolio.dev/u003-a013 | I14: https://github.com/u00317
A15: A014 | B15: U004 | C15: REA Group | D15: Data Analyst | E15: SEEK | F15: 46197 | G15: Rejected | I15: https://github.com/u00425
A16: A015 | B16: U005 | C16: Optus | D16: Network Support Analyst | E16: Referral | F16: 46246 | G16: Withdrawn | I16: https://github.com/u00543
A17: A016 | B17: U001 | C17: Westpac Digital | D17: UI/UX Designer | E17: Referral | F17: 46201 | G17: Offer
A18: A017 | B18: U002 | C18: RetailPlus | D18: Data Analyst | E18: SEEK | F18: 46269 | G18: Rejected
A19: A018 | B19: U003 | C19: Atlassian | D19: QA Engineer | E19: SEEK | F19: 46174 | G19: Archived | I19: https://github.com/u00311
A20: A019 | B20: U004 | C20: Accenture Australia | D20: Product Analyst | E20: Indeed | F20: 46220 | G20: Withdrawn | H20: https://portfolio.dev/u004-a019 | I20: https://github.com/u00423
A21: A020 | B21: U005 | C21: Canva | D21: Software Engineer | E21: LinkedIn | F21: 46196 | G21: Interview | H21: https://portfolio.dev/u005-a020
A22: A021 | B22: U001 | C22: RetailPlus | D22: Data Analyst | E22: Company Website | F22: 46178 | G22: Interview | H22: https://portfolio.dev/u001-a021
A23: A022 | B23: U002 | C23: SEEK Ltd | D23: Associate Software Engineer | E23: Indeed | F23: 46218 | G23: Applied | I23: https://github.com/u00278
A24: A023 | B24: U003 | C24: Atlassian | D24: QA Engineer | E24: SEEK | F24: 46187 | G24: Interview | H24: https://portfolio.dev/u003-a023
A25: A024 | B25: U004 | C25: NAB | D25: Test Analyst | E25: LinkedIn | F25: 46220 | G25: Archived | H25: https://portfolio.dev/u004-a024
A26: A025 | B26: U005 | C26: Qantas | D26: Data Engineer | E26: Company Website | F26: 46263 | G26: Withdrawn | H26: https://portfolio.dev/u005-a025
A27: A026 | B27: U001 | C27: Cochlear | D27: Software Test Engineer | E27: Referral | F27: 46212 | G27: Rejected | H27: https://portfolio.dev/u001-a026 | I27: https://github.com/u00184
A28: A027 | B28: U002 | C28: Telstra | D28: Business Analyst | E28: Referral | F28: 46234 | G28: Withdrawn | H28: https://portfolio.dev/u002-a027
A29: A028 | B29: U003 | C29: Canva | D29: Software Engineer | E29: Company Website | F29: 46252 | G29: Interview | H29: https://portfolio.dev/u003-a028
A30: A029 | B30: U004 | C30: Canva | D30: Software Engineer | E30: LinkedIn | F30: 46263 | G30: Archived | H30: https://portfolio.dev/u004-a029
A31: A030 | B31: U005 | C31: Canva | D31: Software Engineer | E31: Indeed | F31: 46272 | G31: Interview | H31: https://portfolio.dev/u005-a030 | I31: https://github.com/u00566
A32: A031 | B32: U001 | C32: Transport for NSW | D32: Business Analyst | E32: LinkedIn | F32: 46182 | G32: Applied | H32: https://portfolio.dev/u001-a031 | I32: https://github.com/u00169
A33: A032 | B33: U002 | C33: ANZ Bank | D33: Graduate Software Developer | E33: Referral | F33: 46263 | G33: Offer | H33: https://portfolio.dev/u002-a032 | I33: https://github.com/u00255
A34: A033 | B34: U003 | C34: Optus | D34: Network Support Analyst | E34: Referral | F34: 46269 | G34: Rejected | H34: https://portfolio.dev/u003-a033 | I34: https://github.com/u00372
A35: A034 | B35: U004 | C35: Cochlear | D35: Software Test Engineer | E35: Referral | F35: 46177 | G35: Rejected | I35: https://github.com/u00464
A36: A035 | B36: U005 | C36: Qantas | D36: Data Engineer | E36: Indeed | F36: 46271 | G36: Withdrawn | H36: https://portfolio.dev/u005-a035 | I36: https://github.com/u00512
A37: A036 | B37: U001 | C37: Canva | D37: Software Engineer | E37: LinkedIn | F37: 46176 | G37: Offer | H37: https://portfolio.dev/u001-a036 | I37: https://github.com/u00137
A38: A037 | B38: U002 | C38: Service NSW | D38: Digital Support Officer | E38: Company Website | F38: 46224 | G38: Archived | H38: https://portfolio.dev/u002-a037
A39: A038 | B39: U003 | C39: Accenture Australia | D39: Product Analyst | E39: Indeed | F39: 46242 | G39: Rejected | H39: https://portfolio.dev/u003-a038
A40: A039 | B40: U004 | C40: RetailPlus | D40: Data Analyst | E40: Company Website | F40: 46220 | G40: Archived | H40: https://portfolio.dev/u004-a039
...

Sheet StatusHistory
A1: StatusHistoryId | B1: ApplicationId | C1: OldStatus | D1: NewStatus | E1: ChangedDate
A2: SH001 | B2: A001 | C2: Applied | D2: Interview | E2: 46275
A3: SH002 | B3: A001 | C3: Interview | D3: Offer | E3: 46278
A4: SH003 | B4: A002 | C4: Applied | D4: Interview | E4: 46207
A5: SH004 | B5: A002 | C5: Interview | D5: Offer | E5: 46218
A6: SH005 | B6: A003 | C6: Applied | D6: Interview | E6: 46186
A7: SH006 | B7: A003 | C7: Interview | D7: Withdrawn | E7: 46193
A8: SH007 | B8: A003 | C8: Withdrawn | D8: Archived | E8: 46201
A9: SH008 | B9: A005 | C9: Applied | D9: Interview | E9: 46208
A10: SH009 | B10: A005 | C10: Interview | D10: Rejected | E10: 46212
A11: SH010 | B11: A006 | C11: Applied | D11: Interview | E11: 46249
A12: SH011 | B12: A006 | C12: Interview | D12: Rejected | E12: 46256
A13: SH012 | B13: A008 | C13: Applied | D13: Rejected | E13: 46249
... A130: SH129 | B130: A100 | C130: Interview | D130: Withdrawn | E130: 46201

Sheet Document
A1: DocumentId | B1: ApplicationId | C1: Type | D1: VersionName | E1: FileLinkOrNote
A2: D001 | B2: A001 | C2: Resume | D2: Resume_v2 | E2: https://drive.example.com/resumes/u001/Resume_v2.pdf
A3: D002 | B3: A001 | C3: CoverLetter | D3: CoverLetter_Telstra | E3: https://drive.example.com/cover-letters/u001/CoverLetter_Telstra.pdf
A4: D003 | B4: A002 | C4: Resume | D4: Resume_v1 | E4: https://drive.example.com/resumes/u002/Resume_v1.pdf
A5: D004 | B5: A002 | C5: CoverLetter | D5: CoverLetter_ANZ | E5: https://drive.example.com/cover-letters/u002/CoverLetter_ANZ.pdf
A6: D005 | B6: A003 | C6: Resume | D6: Resume_v1 | E6: https://drive.example.com/resumes/u003/Resume_v1.pdf
A7: D006 | B7: A004 | C7: Resume | D7: Resume_v1 | E7: https://drive.example.com/resumes/u004/Resume_v1.pdf
A8: D007 | B8: A004 | C8: CoverLetter | D8: CoverLetter_DataWorks | E8: https://drive.example.com/cover-letters/u004/CoverLetter_DataWorks.pdf
A9: D008 | B9: A005 | C9: Resume | D9: Resume_v2 | E9: https://drive.example.com/resumes/u005/Resume_v2.pdf
A10: D009 | B10: A005 | C10: CoverLetter | D10: CoverLetter_Canva | E10: https://drive.example.com/cover-letters/u005/CoverLetter_Canva.pdf
A11: D010 | B11: A006 | C11: Resume | D11: Resume_v3 | E11: https://drive.example.com/resumes/u001/Resume_v3.pdf
A12: D011 | B12: A006 | C12: CoverLetter | D12: CoverLetter_Optus | E12: https://drive.example.com/cover-letters/u001/CoverLetter_Optus.pdf
... A167: D166 | B167: A100 | C167: Resume | D167: Resume_v3 | E167: https://drive.example.com/resumes/u005/Resume_v3.pdf

Sheet Interview
A1: InterviewId | B1: ApplicationId | C1: InterviewDate | D1: ContactName | E1: ContactEmail | F1: ContactPhone | G1: Notes
A2: I001 | B2: A001 | C2: 46277 | D2: Lucas Anderson | E2: lucas.anderson@telstra.com.au | F2: 0488461803 | G2: Round 1 - Phone screen
A3: I002 | B3: A002 | C3: 46210 | D3: Ava Walker | E3: ava.walker@anzbank.com.au | F3: 0490048665 | G3: Round 1 - Technical interview
A4: I003 | B4: A003 | C4: 46187 | D4: Grace Clark | E4: grace.clark@atlassian.com.au | F4: 0478139880 | G4: Round 1 - Technical interview
A5: I004 | B5: A003 | C5: 46195 | D5: Grace Clark | E5: grace.clark@atlassian.com.au | F5: 0495758349 | G5: Round 2 - Final round with hiring manager
A6: I005 | B6: A005 | C6: 46209 | D6: Ethan Anderson | E6: ethan.anderson@canva.com.au | F6: 0445575298 | G6: Round 1 - Final round with hiring manager
A7: I006 | B7: A006 | C7: 46249 | D7: Grace Kumar | E7: grace.kumar@optus.com.au | F7: 0443273328 | G7: Round 1 - Behavioural interview
A8: I007 | B8: A011 | C8: 46242 | D8: Ella Clark | E8: ella.clark@canva.com.au | F8: 0432321899 | G8: Round 1 - Phone screen
A9: I008 | B9: A013 | C9: 46277 | D9: Sarah Nguyen | E9: sarah.nguyen@nswgovernment.com.au | F9: 0477491435 | G9: Round 1 - Final round with hiring manager
A10: I009 | B10: A015 | C10: 46256 | D10: Mia Wilson | E10: mia.wilson@optus.com.au | F10: 0452436584 | G10: Round 1 - Technical interview
A11: I010 | B11: A016 | C11: 46208 | D11: Ryan Anderson | E11: ryan.anderson@westpacdigital.com.au | F11: 0492097999 | G11: Round 1 - Final round with hiring manager
A12: I011 | B12: A016 | C12: 46213 | D12: Ryan Anderson | E12: ryan.anderson@westpacdigital.com.au | F12: 0499639081 | G12: Round 2 - Final round with hiring manager
A13: I012 | B13: A017 | C13: 46279 | D13: Ryan Wilson | E13: ryan.wilson@retailplus.com.au | F13: 0443704923 | G13: Round 1 - Technical interview
... A64: I063 | B64: A100 | C64: 46194 | D64: Mia Singh | E64: mia.singh@macquariegroup.com.au | F64: 0496707983 | G64: Round 1 - Phone screen

Sheet FollowUp
A1: FollowUpId | B1: ApplicationId | C1: FollowUpDate | D1: Notes | E1: IsCompleted | G1: Reference date for overdue calculation: 13 Sep 2026 (FR-INT-04 / FR-DASH-03)
A2: F001 | B2: A002 | C2: 46282 | D2: Thank-you note after interview. | E2: =FALSE() -> FALSE | G2: Red fill = overdue (date in the past, not completed). Green fill = completed.
A3: F002 | B3: A004 | C3: 46266 | D3: Confirm interview panel availability. | E3: =FALSE() -> FALSE
A4: F003 | B4: A006 | C4: 46246 | D4: Follow-up sent before outcome was known. | E4: =TRUE() -> TRUE
A5: F004 | B5: A009 | C5: 46284 | D5: Send a polite follow-up email if no response. | E5: =FALSE() -> FALSE
A6: F005 | B6: A014 | C6: 46201 | D6: Follow-up sent before outcome was known. | E6: =TRUE() -> TRUE
A7: F006 | B7: A015 | C7: 46250 | D7: Follow-up sent before outcome was known. | E7: =TRUE() -> TRUE
A8: F007 | B8: A016 | C8: 46280 | D8: Confirm interview panel availability. | E8: =FALSE() -> FALSE
A9: F008 | B9: A017 | C9: 46278 | D9: Follow-up sent before outcome was known. | E9: =TRUE() -> TRUE
A10: F009 | B10: A018 | C10: 46179 | D10: Follow-up sent before outcome was known. | E10: =TRUE() -> TRUE
A11: F010 | B11: A021 | C11: 46281 | D11: Send a polite follow-up email if no response. | E11: =FALSE() -> FALSE
A12: F011 | B12: A022 | C12: 46223 | D12: Thank-you note after interview. | E12: =TRUE() -> TRUE
A13: F012 | B13: A023 | C13: 46190 | D13: Thank-you note after interview. | E13: =TRUE() -> TRUE
A14: F013 | B14: A027 | C14: 46237 | D14: Follow-up sent before outcome was known. | E14: =TRUE() -> TRUE
A15: F014 | B15: A028 | C15: 46274 | D15: Ask about expected decision timeline. | E15: =FALSE() -> FALSE
A16: F015 | B16: A030 | C16: 46265 | D16: Check in with recruiter on next steps. | E16: =FALSE() -> FALSE
A17: F016 | B17: A040 | C17: 46260 | D17: Confirm interview panel availability. | E17: =TRUE() -> TRUE
A18: F017 | B18: A041 | C18: 46268 | D18: Check in with recruiter on next steps. | E18: =FALSE() -> FALSE
A19: F018 | B19: A042 | C19: 46274 | D19: Check in with recruiter on next steps. | E19: =FALSE() -> FALSE
A20: F019 | B20: A043 | C20: 46281 | D20: Send a polite follow-up email if no response. | E20: =FALSE() -> FALSE
A21: F020 | B21: A044 | C21: 46197 | D21: Ask about expected decision timeline. | E21: =TRUE() -> TRUE
A22: F021 | B22: A049 | C22: 46281 | D22: Check in with recruiter on next steps. | E22: =FALSE() -> FALSE
A23: F022 | B23: A050 | C23: 46279 | D23: Thank-you note after interview. | E23: =FALSE() -> FALSE
A24: F023 | B24: A052 | C24: 46265 | D24: Thank-you note after interview. | E24: =FALSE() -> FALSE
A25: F024 | B25: A056 | C25: 46258 | D25: Thank-you note after interview. | E25: =FALSE() -> FALSE
A26: F025 | B26: A059 | C26: 46261 | D26: Thank-you note after interview. | E26: =FALSE() -> FALSE
A27: F026 | B27: A061 | C27: 46268 | D27: Check in with recruiter on next steps. | E27: =FALSE() -> FALSE
A28: F027 | B28: A062 | C28: 46232 | D28: Confirm interview panel availability. | E28: =TRUE() -> TRUE
A29: F028 | B29: A066 | C29: 46196 | D29: Confirm interview panel availability. | E29: =TRUE() -> TRUE
A30: F029 | B30: A068 | C30: 46264 | D30: Check in with recruiter on next steps. | E30: =FALSE() -> FALSE
A31: F030 | B31: A070 | C31: 46284 | D31: Confirm interview panel availability. | E31: =FALSE() -> FALSE
A32: F031 | B32: A077 | C32: 46283 | D32: Send a polite follow-up email if no response. | E32: =FALSE() -> FALSE
A33: F032 | B33: A078 | C33: 46222 | D33: Follow-up sent before outcome was known. | E33: =TRUE() -> TRUE
A34: F033 | B34: A081 | C34: 46223 | D34: Follow-up sent before outcome was known. | E34: =TRUE() -> TRUE
A35: F034 | B35: A082 | C35: 46283 | D35: Thank-you note after interview. | E35: =FALSE() -> FALSE
A36: F035 | B36: A084 | C36: 46266 | D36: Follow-up sent before outcome was known. | E36: =TRUE() -> TRUE
A37: F036 | B37: A086 | C37: 46261 | D37: Send a polite follow-up email if no response. | E37: =FALSE() -> FALSE
A38: F037 | B38: A088 | C38: 46209 | D38: Follow-up sent before outcome was known. | E38: =TRUE() -> TRUE
A39: F038 | B39: A091 | C39: 46185 | D39: Follow-up sent before outcome was known. | E39: =TRUE() -> TRUE
A40: F039 | B40: A094 | C40: 46283 | D40: Ask about expected decision timeline. | E40: =FALSE() -> FALSE
...

Sheet Data Dictionary
A1: Entity | B1: Field | C1: Description | D1: Example
A2: User | B2: UserId | C2: Unique identifier for a registered user. | D2: U001
A3: User | B3: Email | C3: User's login email; must be unique (FR-AUTH-01). | D3: prince.sah@example.com
A4: User | B4: PasswordHash | C4: Securely hashed password, never stored in plain text (NFR-02). Placeholder values only. | D4: $2b$12$...
A5: User | B5: CreatedDate | C5: Date the account was registered. | D5: 01 Jun 2026
A6: User | B6: Name (supplementary) | C6: Human-readable label, not part of the BRD/SRS User entity. | D6: Prince Kumar Sah
A7: Application | B7: ApplicationId | C7: Unique identifier for a job application record. | D7: A001
A8: Application | B8: UserId | C8: Owning user; enforces per-user data isolation (FR-AUTH-03). | D8: U001
A9: Application | B9: CompanyName | C9: Employer name (FR-APP-01, mandatory). | D9: Telstra
A10: Application | B10: RoleTitle | C10: Job title applied for (FR-APP-01, mandatory). | D10: Business Analyst
A11: Application | B11: Platform | C11: Channel the application was submitted through (FR-APP-01, mandatory). | D11: LinkedIn
A12: Application | B12: ApplicationDate | C12: Date the application was submitted (FR-APP-01, mandatory). | D12: 31 Aug 2026
... A37: FollowUp | B37: IsCompleted | C37: Whether the follow-up action has been done; overdue = date passed AND not completed (FR-INT-04, FR-DASH-03). | D37: TRUE
